Workbook
Name USD: [1]SUMMARY!#REF!
Name 슬라이서_Parts: #N/A
Name 슬라이서_Shuttle: #N/A

Sheet Parts
A1: PARTS LIST | G1: 안전재고 | H1: 전체 ITEM | I1: 안전재고 부족 | J1: Safety Stock Fulfillment Rate
G2: ASRS | H2: =COUNTIFS(A:A,G2) -> 349 | I2: =COUNTIFS(A:A,G2,J:J,"X") -> 1 | J2: =(H2-I2)/H2 -> 0.99713467
G3: CONVEYOR | H3: =COUNTIFS(A:A,G3) -> 703 | I3: =COUNTIFS(A:A,G3,J:J,"X") -> 33 | J3: =(H3-I3)/H3 -> 0.95305832
G4: UTILITY | H4: =COUNTIFS(A:A,G4) -> 192 | I4: =COUNTIFS(A:A,G4,J:J,"X") -> 7 | J4: =(H4-I4)/H4 -> 0.96354167 | AB4: 입력날짜 | AC4: 45961 | AD4: 45989 | AE4: 46022 | AF4: 45687 | AG4: 46080 | AH4: 46112
G5: ELECTRICAL | H5: =COUNTIFS(A:A,G5) -> 71 | I5: =COUNTIFS(A:A,G5,J:J,"X") -> 0 | J5: =(H5-I5)/H5 -> 1 | P5: 1712 | AC5: FY26 | AK5: FY27 | AL5: FY27 | AM5: FY27 | AN5: FY27 | AO5: FY27 | AP5: FY27 | AQ5: FY27 | AR5: FY27 | AS5: FY27 | AT5: FY27 | AU5: FY27 | AV5: FY27
A6: EQUIPMENT | B6: Hierarchy-1 | C6: Hierarchy-2 | D6: Hierarchy-3 | E6: Hierarchy-4 | F6: 설치설비 | G6: 설치갯수 | H6: 현재재고 | I6: 안전재고 | J6: 안전재고 충족현황 | K6: 보관 위치 | L6: Supplier | M6: 제조사 | N6: Order number | O6: Unit price (EUR) | P6: Unit price (KRW) | Q6: Life time | R6: Lead time | S6: Criticality | T6: Demend per year | U6: 입고예정 | V6: 입고 후 총 수량 | W6: 2차분 입고수량 | X6: 기존수량+입고수량 | AC6: Oct | AD6: Nov | AE6: Dec | AF6: Jan | AG6: Feb | AH6: Mar | AI6: Apr | AJ6: May | AK6: Jun | AL6: Jul | AM6: Aug | AN6: Sep | AO6: Oct | AP6: Nov | AQ6: Dec | AR6: Jan | AS6: Feb | AT6: Mar | AU6: Apr | AV6: May | AW6: Jun | AX6: Jul | AY6: Aug | AZ6: Sep | BA6: Oct | BB6: Nov | BC6: Dec | BD6: Jan | BE6: Feb | BF6: Mar | BG6: Apr | BH6: May
A7: Conveyor | B7: KNAPP Conveyor | C7: Motorized roller | D7: NB=660 EC5000 18:1 P... | E7: EL 660, RL:646mm | F7: WE01, WE02, WA01, WA02, TK01, TK03 | G7: 56 | H7: 3 | I7: =MIN(10,MAX(1,ROUNDUP(IFERROR(IF(OR(G7="",G7=0),1,G7),1)*0.1*90/365,0))) -> 2 | J7: =IF(H7<I7,"X","O") -> O | K7: C14 | M7: Interoll | N7: 10325252_01_0004 | W7: =_xlfn.XLOOKUP(N7,#REF!,#REF!,"없음") -> #REF! | Y7: =_xlfn.XLOOKUP(N7,#REF!,#REF!,"없음") -> #REF! | AA7: % | AB7: ASRS | AC7: 0.88554217 | AD7: 0.88554217 | AE7: 0.91 | AF7: 0.9 | AG7: 0.97
A8: Conveyor | B8: KNAPP Conveyor | C8: Motorized roller | D8: NB=900 EC5000 18:1 P... | E8: EL 900, RL:886mm | F8: WE01, WE02, WA02, TK01, TK03 | G8: 50 | H8: 2 | I8: =MIN(10,MAX(1,ROUNDUP(IFERROR(IF(OR(G8="",G8=0),1,G8),1)*0.1*90/365,0))) -> 2 | J8: =IF(H8<I8,"X","O") -> O | K8: C14 | M8: Interoll | N8: 10325252_01_0027 | W8: =_xlfn.XLOOKUP(N8,#REF!,#REF!,"없음") -> #REF! | Y8: =_xlfn.XLOOKUP(N8,#REF!,#REF!,"없음") -> #REF! | AA8: % | AB8: CONVEYOR | AC8: 0.73940345 | AD8: 0.83832335 | AE8: 0.91 | AF8: 0.95 | AG8: 0.95
A9: Conveyor | B9: KNAPP Conveyor | C9: Motorized roller | D9: NB1=660 EC5000 13:1 ... | E9: EL 660 | F9: WE01 | G9: 5 | H9: 3 | I9: =MIN(10,MAX(1,ROUNDUP(IFERROR(IF(OR(G9="",G9=0),1,G9),1)*0.1*90/365,0))) -> 1 | J9: =IF(H9<I9,"X","O") -> O | K9: C14 | M9: Interoll | N9: 10327146_01_0002 | W9: =_xlfn.XLOOKUP(N9,#REF!,#REF!,"없음") -> #REF! | Y9: =_xlfn.XLOOKUP(N9,#REF!,#REF!,"없음") -> #REF! | AA9: % | AB9: UTILITY | AC9: 1 | AD9: 1 | AE9: 0.98 | AF9: 0.98 | AG9: 0.98
A10: Conveyor | B10: KNAPP Conveyor | C10: Motorized roller | D10: 746 EC5000 35W 18:1 / EC310 30/22 16:1 62421074/0017 | E10: RL:736mm | G10: 76 | H10: 2 | I10: =MIN(10,MAX(1,ROUNDUP(IFERROR(IF(OR(G10="",G10=0),1,G10),1)*0.1*90/365,0))) -> 2 | J10: =IF(H10<I10,"X","O") -> O | K10: C14 | M10: Interoll | N10: 10805810_01_0044 | W10: =_xlfn.XLOOKUP(N10,#REF!,#REF!,"없음") -> #REF! | Y10: =_xlfn.XLOOKUP(N10,#REF!,#REF!,"없음") -> #REF! | AA10: % | AB10: ELECTRICAL | AC10: 1 | AD10: 1 | AE10: 1 | AF10: 1 | AG10: 1
A11: Conveyor | B11: KNAPP Conveyor | C11: Motorized roller | D11: 746 50 ST 18:1 PV EC5000 | E11: RL:736mm | G11: 51 | H11: 2 | I11: =MIN(10,MAX(1,ROUNDUP(IFERROR(IF(OR(G11="",G11=0),1,G11),1)*0.1*90/365,0))) -> 2 | J11: =IF(H11<I11,"X","O") -> O | K11: C14 | M11: Interoll | N11: 10661784_01_0044 | W11: =_xlfn.XLOOKUP(N11,#REF!,#REF!,"없음") -> #REF! | Y11: =_xlfn.XLOOKUP(N11,#REF!,#REF!,"없음") -> #REF! | AA11: Total item | AB11: ASRS | AC11: 332 | AD11: 332 | AE11: 344 | AF11: 346 | AG11: 346
A12: Conveyor | B12: KNAPP Conveyor | C12: Motorized roller | D12: NB=750 EC310 16-1 PV / EC5000 35W A1 18:1 TYPE2 DE01339523 | E12: Taper, RL:736mm, 검정색 | G12: 42 | H12: 2 | I12: =MIN(10,MAX(1,ROUNDUP(IFERROR(IF(OR(G12="",G12=0),1,G12),1)*0.1*90/365,0))) -> 2 | J12: =IF(H12<I12,"X","O") -> O | K12: C14 | M12: Interoll | N12: 10330501_01_0010 | W12: =_xlfn.XLOOKUP(N12,#REF!,#REF!,"없음") -> #REF! | Y12: =_xlfn.XLOOKUP(N12,#REF!,#REF!,"없음") -> #REF! | AA12: Total item | AB12: CONVEYOR | AC12: 637 | AD12: 668 | AE12: 671 | AF12: 702 | AG12: 703
A13: Conveyor | B13: KNAPP Conveyor | C13: Motorized roller | D13: 716 EC5000 35W 18:1 | E13: RL:706mm | G13: 19 | H13: 2 | I13: =MIN(10,MAX(1,ROUNDUP(IFERROR(IF(OR(G13="",G13=0),1,G13),1)*0.1*90/365,0))) -> 1 | J13: =IF(H13<I13,"X","O") -> O | K13: C14 | M13: Interoll | N13: 10805810_01_0042 | W13: =_xlfn.XLOOKUP(N13,#REF!,#REF!,"없음") -> #REF! | Y13: =_xlfn.XLOOKUP(N13,#REF!,#REF!,"없음") -> #REF! | AA13: Total item | AB13: UTILITY | AC13: 179 | AD13: 179 | AE13: 192 | AF13: 192 | AG13: 192
A14: Conveyor | B14: KNAPP Conveyor | C14: Motorized roller | D14: 296 50 ST 13:1 PV EC... | E14: 296 | F14: WE01, WE02 | G14: 4 | H14: 2 | I14: =MIN(10,MAX(1,ROUNDUP(IFERROR(IF(OR(G14="",G14=0),1,G14),1)*0.1*90/365,0))) -> 1 | J14: =IF(H14<I14,"X","O") -> O | K14: C13 | M14: Interoll | N14: 10661659_01_0003 | W14: =_xlfn.XLOOKUP(N14,#REF!,#REF!,"없음") -> #REF! | Y14: =_xlfn.XLOOKUP(N14,#REF!,#REF!,"없음") -> #REF! | AA14: Total item | AB14: ELECTRICAL | AC14: 71 | AD14: 71 | AE14: 71 | AF14: 71 | AG14: 71
A15: Conveyor | B15: KNAPP Conveyor | C15: Motorized roller | D15: 326 50 ST 13:1 PV EC5000 | E15: 326, RL:316mm | F15: WE01, WE02, WA02, WA03 | G15: 10 | H15: 3 | I15: =MIN(10,MAX(1,ROUNDUP(IFERROR(IF(OR(G15="",G15=0),1,G15),1)*0.1*90/365,0))) -> 1 | J15: =IF(H15<I15,"X","O") -> O | K15: C13 | M15: Interoll | N15: 10661659_01_0005 | W15: =_xlfn.XLOOKUP(N15,#REF!,#REF!,"없음") -> #REF! | Y15: =_xlfn.XLOOKUP(N15,#REF!,#REF!,"없음") -> #REF! | AA15: 부족 | AB15: ASRS | AC15: 38 | AD15: 38 | AE15: 32 | AF15: 35 | AG15: 10
A16: Conveyor | B16: KNAPP Conveyor | C16: Motorized roller | D16: 626 50 ST 13:1 PV EC... | E16: 626 | F16: WE01 | G16: 1 | H16: 1 | I16: =MIN(10,MAX(1,ROUNDUP(IFERROR(IF(OR(G16="",G16=0),1,G16),1)*0.1*90/365,0))) -> 1 | J16: =IF(H16<I16,"X","O") -> O | K16: C14 | M16: Interoll | N16: 10661659_01_0034 | W16: =_xlfn.XLOOKUP(N16,#REF!,#REF!,"없음") -> #REF! | Y16: =_xlfn.XLOOKUP(N16,#REF!,#REF!,"없음") -> #REF! | AA16: 부족 | AB16: CONVEYOR | AC16: 166 | AD16: 108 | AE16: 60 | AF16: 38 | AG16: 34
A17: Conveyor | B17: KNAPP Conveyor | C17: Motorized roller | D17: 656 50 ST 13:1 PV EC5000 | E17: 656, RL:646mm | F17: WE01, WE02, WA01, WA02 | G17: 21 | H17: 3 | I17: =MIN(10,MAX(1,ROUNDUP(IFERROR(IF(OR(G17="",G17=0),1,G17),1)*0.1*90/365,0))) -> 1 | J17: =IF(H17<I17,"X","O") -> O | K17: C14 | M17: Interoll | N17: 10661659_01_0038 | W17: =_xlfn.XLOOKUP(N17,#REF!,#REF!,"없음") -> #REF! | Y17: =_xlfn.XLOOKUP(N17,#REF!,#REF!,"없음") -> #REF! | AA17: 부족 | AB17: UTILITY | AC17: 0 | AD17: 0 | AE17: 3 | AF17: 3 | AG17: 3
A18: Conveyor | B18: KNAPP Conveyor | C18: Motorized roller | D18: 656 50 ST 13:1 PV GU... | E18: 656 | F18: WE01 | G18: 5 | H18: 1 | I18: =MIN(10,MAX(1,ROUNDUP(IFERROR(IF(OR(G18="",G18=0),1,G18),1)*0.1*90/365,0))) -> 1 | J18: =IF(H18<I18,"X","O") -> O | K18: C14 | M18: Interoll | N18: 10661780_01_0027 | W18: =_xlfn.XLOOKUP(N18,#REF!,#REF!,"없음") -> #REF! | Y18: =_xlfn.XLOOKUP(N18,#REF!,#REF!,"없음") -> #REF! | AA18: 부족 | AB18: ELECTRICAL | AC18: 0 | AD18: 0 | AE18: 0 | AF18: 0 | AG18: 0
A19: Conveyor | B19: KNAPP Conveyor | C19: Motorized roller | D19: 266 50 ST 18:1 PV EC5000 | E19: 266, RL:256mm | F19: WE01, WE02, WA01, WA02, WA03, TK01, TK02, TK03 | G19: 54 | H19: 3 | I19: =MIN(10,MAX(1,ROUNDUP(IFERROR(IF(OR(G19="",G19=0),1,G19),1)*0.1*90/365,0))) -> 2 | J19: =IF(H19<I19,"X","O") -> O | K19: C13 | M19: Interoll | N19: 10661784_01_0001 | W19: =_xlfn.XLOOKUP(N19,#REF!,#REF!,"없음") -> #REF! | Y19: =_xlfn.XLOOKUP(N19,#REF!,#REF!,"없음") -> #REF!
A20: Conveyor | B20: KNAPP Conveyor | C20: Motorized roller | D20: 626 50 ST 18:1 PV EC5000 | E20: 626, RL:616mm | F20: WE01, WE02, WA01, WA02, TK01, TK03 | G20: 47 | H20: 3 | I20: =MIN(10,MAX(1,ROUNDUP(IFERROR(IF(OR(G20="",G20=0),1,G20),1)*0.1*90/365,0))) -> 2 | J20: =IF(H20<I20,"X","O") -> O | K20: C14 | M20: Interoll | N20: 10661784_01_0034 | W20: =_xlfn.XLOOKUP(N20,#REF!,#REF!,"없음") -> #REF! | Y20: =_xlfn.XLOOKUP(N20,#REF!,#REF!,"없음") -> #REF!
A21: Conveyor | B21: KNAPP Conveyor | C21: Motorized roller | D21: 656 50 ST 18:1 PV EC5000 | E21: 656, RL:646mm | F21: WE01, WE02, WA01, WA02, TK01, TK03 | G21: 100 | H21: 3 | I21: =MIN(10,MAX(1,ROUNDUP(IFERROR(IF(OR(G21="",G21=0),1,G21),1)*0.1*90/365,0))) -> 3 | J21: =IF(H21<I21,"X","O") -> O | K21: C14 | M21: Interoll | N21: 10661784_01_0038 | W21: =_xlfn.XLOOKUP(N21,#REF!,#REF!,"없음") -> #REF! | Y21: =_xlfn.XLOOKUP(N21,#REF!,#REF!,"없음") -> #REF!
A22: Conveyor | B22: KNAPP Conveyor | C22: Motorized roller | D22: 896 50 ST 18:1 PV EC5000 | E22: 896, RL:886mm | F22: WE01, WE02, WA02, TK01, TK03 | G22: 72 | H22: 6 | I22: =MIN(10,MAX(1,ROUNDUP(IFERROR(IF(OR(G22="",G22=0),1,G22),1)*0.1*90/365,0))) -> 2 | J22: =IF(H22<I22,"X","O") -> O | K22: C14 | M22: Interoll | N22: 10661784_01_0054 | W22: =_xlfn.XLOOKUP(N22,#REF!,#REF!,"없음") -> #REF! | Y22: =_xlfn.XLOOKUP(N22,#REF!,#REF!,"없음") -> #REF!
A23: Conveyor | B23: KNAPP Conveyor | C23: Motorized roller | D23: 656 50 ST 18:1 PV GU... / EC5000 35W A1 18:1 TYPE2 48/24 DE1397590 | E23: 656 | F23: WE01, WA01, TK01, TK03 | G23: 9 | H23: 8 | I23: =MIN(10,MAX(1,ROUNDUP(IFERROR(IF(OR(G23="",G23=0),1,G23),1)*0.1*90/365,0))) -> 1 | J23: =IF(H23<I23,"X","O") -> O | K23: A21 | M23: Interoll | N23: 10661785_01_0027 | W23: =_xlfn.XLOOKUP(N23,#REF!,#REF!,"없음") -> #REF! | Y23: =_xlfn.XLOOKUP(N23,#REF!,#REF!,"없음") -> #REF!
A24: Conveyor | B24: KNAPP Conveyor | C24: Motorized roller | D24: 656 50 ST 13:1 PV KO... | E24: Taper ,656 | F24: WE01, WA02 | G24: 3 | H24: 2 | I24: =MIN(10,MAX(1,ROUNDUP(IFERROR(IF(OR(G24="",G24=0),1,G24),1)*0.1*90/365,0))) -> 1 | J24: =IF(H24<I24,"X","O") -> O | K24: C14 | M24: Interoll | N24: 10661867_01_0008 | W24: =_xlfn.XLOOKUP(N24,#REF!,#REF!,"없음") -> #REF! | Y24: =_xlfn.XLOOKUP(N24,#REF!,#REF!,"없음") -> #REF!
A25: Conveyor | B25: KNAPP Conveyor | C25: Motorized roller | D25: 656 50 ST 18:1 PV KO... / EC5000 35W A1 18:1 TYPE2 T 47/24 DE01390941 | E25: Taper, 656, RL:646mm | F25: WE01, WE02, WA01, WA02, TK01, TK03 | G25: 9 | H25: 2 | I25: =MIN(10,MAX(1,ROUNDUP(IFERROR(IF(OR(G25="",G25=0),1,G25),1)*0.1*90/365,0))) -> 1 | J25: =IF(H25<I25,"X","O") -> O | K25: C14 | M25: Interoll | N25: 10661869_01_0008 | W25: =_xlfn.XLOOKUP(N25,#REF!,#REF!,"없음") -> #REF! | Y25: =_xlfn.XLOOKUP(N25,#REF!,#REF!,"없음") -> #REF!
A26: Conveyor | B26: KNAPP Conveyor | C26: Motorized roller | D26: 866 50 ST 18:1 PV EC5000 | E26: 866, RL:656mm | F26: WE02, TK01, TK03 | G26: 34 | H26: 3 | I26: =MIN(10,MAX(1,ROUNDUP(IFERROR(IF(OR(G26="",G26=0),1,G26),1)*0.1*90/365,0))) -> 1 | J26: =IF(H26<I26,"X","O") -> O | K26: C14 | M26: Interoll | N26: 10661784_01_0052 | W26: =_xlfn.XLOOKUP(N26,#REF!,#REF!,"없음") -> #REF! | Y26: =_xlfn.XLOOKUP(N26,#REF!,#REF!,"없음") -> #REF!
A27: Conveyor | B27: KNAPP Conveyor | C27: Motorized roller | D27: NB=840 EC5000 18:1 P... | E27: 840 | F27: WA01 | G27: 1 | H27: 1 | I27: =MIN(10,MAX(1,ROUNDUP(IFERROR(IF(OR(G27="",G27=0),1,G27),1)*0.1*90/365,0))) -> 1 | J27: =IF(H27<I27,"X","O") -> O | K27: C14 | M27: Interoll | N27: 10325252_01_0010 | W27: =_xlfn.XLOOKUP(N27,#REF!,#REF!,"없음") -> #REF! | Y27: =_xlfn.XLOOKUP(N27,#REF!,#REF!,"없음") -> #REF!
A28: Conveyor | B28: KNAPP Conveyor | C28: Motorized roller | D28: 266 50 ST 13:1 PV EC... | E28: 266 | F28: WA01 | G28: 2 | H28: 2 | I28: =MIN(10,MAX(1,ROUNDUP(IFERROR(IF(OR(G28="",G28=0),1,G28),1)*0.1*90/365,0))) -> 1 | J28: =IF(H28<I28,"X","O") -> O | K28: C13 | M28: Interoll | N28: 10661659_01_0001 | W28: =_xlfn.XLOOKUP(N28,#REF!,#REF!,"없음") -> #REF! | Y28: =_xlfn.XLOOKUP(N28,#REF!,#REF!,"없음") -> #REF!
A29: Conveyor | B29: KNAPP Conveyor | C29: Motorized roller | D29: 836 50 ST 18:1 PV EC... | E29: 836 | F29: WA01 | G29: 1 | H29: 1 | I29: =MIN(10,MAX(1,ROUNDUP(IFERROR(IF(OR(G29="",G29=0),1,G29),1)*0.1*90/365,0))) -> 1 | J29: =IF(H29<I29,"X","O") -> O | K29: C14 | M29: Interoll | N29: 10661784_01_0050 | W29: =_xlfn.XLOOKUP(N29,#REF!,#REF!,"없음") -> #REF! | Y29: =_xlfn.XLOOKUP(N29,#REF!,#REF!,"없음") -> #REF!
A30: Conveyor | B30: KNAPP Conveyor | C30: Motorized roller | D30: NB=900 Int MR -M, ST... | E30: 900 | F30: TK01 | G30: 8 | H30: 10 | I30: =MIN(10,MAX(1,ROUNDUP(IFERROR(IF(OR(G30="",G30=0),1,G30),1)*0.1*90/365,0))) -> 1 | J30: =IF(H30<I30,"X","O") -> O | K30: 0 | M30: Interoll | N30: 10328021_02_0017 | W30: =_xlfn.XLOOKUP(N30,#REF!,#REF!,"없음") -> #REF! | Y30: =_xlfn.XLOOKUP(N30,#REF!,#REF!,"없음") -> #REF!
A31: Conveyor | B31: KNAPP Conveyor | C31: Motorized roller | D31: 956 50 ST 18:1 PV EC... | E31: 956 | F31: TK01 | G31: 1 | H31: 1 | I31: =MIN(10,MAX(1,ROUNDUP(IFERROR(IF(OR(G31="",G31=0),1,G31),1)*0.1*90/365,0))) -> 1 | J31: =IF(H31<I31,"X","O") -> O | K31: C14 | M31: Interoll | N31: 10661784_01_0058 | W31: =_xlfn.XLOOKUP(N31,#REF!,#REF!,"없음") -> #REF! | Y31: =_xlfn.XLOOKUP(N31,#REF!,#REF!,"없음") -> #REF!
A32: Conveyor | B32: KNAPP Conveyor | C32: Motorized roller | D32: 846 50 ST 18:1 PV EC5000 | E32: 846, RL:836mm | F32: SH01, SH02 | G32: 65 | H32: 3 | I32: 5 | J32: =IF(H32<I32,"X","O") -> X | K32: C14 | M32: Interoll | N32: 10661784_01_0051 | W32: =_xlfn.XLOOKUP(N32,#REF!,#REF!,"없음") -> #REF! | Y32: =_xlfn.XLOOKUP(N32,#REF!,#REF!,"없음") -> #REF!
A33: Conveyor | B33: KNAPP Conveyor | C33: Motorized roller | D33: 921 50 ST 18:1 PV EC5000 | E33: 921, RL:912mm | F33: SH01, SH02 | G33: 177 | H33: 3 | I33: =MIN(10,MAX(1,ROUNDUP(IFERROR(IF(OR(G33="",G33=0),1,G33),1)*0.1*90/365,0))) -> 5 | J33: =IF(H33<I33,"X","O") -> X | K33: C14 | M33: Interoll | N33: 10661784_01_0055 | W33: =_xlfn.XLOOKUP(N33,#REF!,#REF!,"없음") -> #REF! | Y33: =_xlfn.XLOOKUP(N33,#REF!,#REF!,"없음") -> #REF!
A34: Conveyor | B34: KNAPP Conveyor | C34: Motorized roller mounting plate | D34: Right side | E34: 파워롤러 서포트 | H34: 1 | I34: =MIN(10,MAX(1,ROUNDUP(IFERROR(IF(OR(G34="",G34=0),1,G34),1)*0.1*90/365,0))) -> 1 | J34: =IF(H34<I34,"X","O") -> O | K34: A22 | L34: KNAPP | M34: KNAPP | N34: 10324754_02 | W34: =_xlfn.XLOOKUP(N34,#REF!,#REF!,"없음") -> #REF! | Y34: =_xlfn.XLOOKUP(N34,#REF!,#REF!,"없음") -> #REF!
A35: Conveyor | B35: KNAPP Conveyor | C35: Motorized roller mounting plate | D35: Left side | E35: 파워롤러 서포트 | H35: 3 | I35: =MIN(10,MAX(1,ROUNDUP(IFERROR(IF(OR(G35="",G35=0),1,G35),1)*0.1*90/365,0))) -> 1 | J35: =IF(H35<I35,"X","O") -> O | K35: A22 | L35: KNAPP | M35: KNAPP | N35: 10324754_03 | W35: =_xlfn.XLOOKUP(N35,#REF!,#REF!,"없음") -> #REF! | Y35: =_xlfn.XLOOKUP(N35,#REF!,#REF!,"없음") -> #REF!
A36: Conveyor | B36: KNAPP Conveyor | C36: Gear motor | D36: SEW 0.55kw/14.33 | E36: WA30DRN80MK4 50.8265610608.0001.23 | F36: TK01, TK03, WA02, WE01 | G36: 39 | H36: 2 | I36: 2 | J36: =IF(H36<I36,"X","O") -> O | K36: B12 | M36: SEW | N36: 10671423 | W36: =_xlfn.XLOOKUP(N36,#REF!,#REF!,"없음") -> #REF! | Y36: =_xlfn.XLOOKUP(N36,#REF!,#REF!,"없음") -> #REF!
A37: Conveyor | B37: KNAPP Conveyor | C37: Gear motor | D37: SEW 0.75kw/8.2 | E37: WA30DRN80M4 50.8265610603.0001.23 | F37: MK01, TK02, TK03, WA01, WA02, WE02 | G37: 22 | H37: 4 | I37: 3 | J37: =IF(H37<I37,"X","O") -> O | K37: B12 | M37: SEW | N37: 10690980 | W37: =_xlfn.XLOOKUP(N37,#REF!,#REF!,"없음") -> #REF! | X37: 5 | Y37: =_xlfn.XLOOKUP(N37,#REF!,#REF!,"없음") -> #REF! | Z37: KNAPP 2차 SPARE PARTS 추가 입고됨
A38: Conveyor | B38: KNAPP Conveyor | C38: Gear motor | D38: SEW 0.75kw/10.25 | E38: WA30DRN80M4 50.8265610604.0001.23 | F38: MK01, TK01, TK03, WA02, WA03, WE02, ZENB | G38: 19 | H38: 3 | I38: 2 | J38: =IF(H38<I38,"X","O") -> O | K38: B12 | M38: SEW | N38: 10690919 | W38: =_xlfn.XLOOKUP(N38,#REF!,#REF!,"없음") -> #REF! | Y38: =_xlfn.XLOOKUP(N38,#REF!,#REF!,"없음") -> #REF!
A39: Conveyor | B39: KNAPP Conveyor | C39: Gear motor | D39: SEW 0.55kw/8.2 | E39: WA30DRN80MK4 50.8265610609.0001.23 | F39: MK01, TK01, TK03, WA02. WA03, WE01, WE02, ZENB | G39: 19 | H39: 3 | I39: 2 | J39: =IF(H39<I39,"X","O") -> O | K39: B12 | M39: SEW | N39: 10671421 | W39: =_xlfn.XLOOKUP(N39,#REF!,#REF!,"없음") -> #REF! | Y39: =_xlfn.XLOOKUP(N39,#REF!,#REF!,"없음") -> #REF!
A40: Conveyor | B40: KNAPP Conveyor | C40: Gear motor | D40: SEW 0.55kw/10.25 | E40: WA30DRN80MK4 50.8272419803.0001.23 | F40: MK01, TK02, WA02, WA03, WE01 | G40: 10 | H40: 2 | I40: 2 | J40: =IF(H40<I40,"X","O") -> O | K40: B12 | M40: SEW | N40: 10671424 | W40: =_xlfn.XLOOKUP(N40,#REF!,#REF!,"없음") -> #REF! | Y40: =_xlfn.XLOOKUP(N40,#REF!,#REF!,"없음") -> #REF!
...

Sheet Parts purchase
A1: Order type | B1: Owner | C1: Order & Request date | D1: Vendor | E1: Order NO. | F1: Description | G1: 한글 설명 | H1: 주문 수량 | I1: UNIT | J1: 입고일
A2: NIKE ORDER | C2: 45211 | D2: DLS | E2: 10411034_01 | F2: GEAR MOTOR ELR 220/10/3500 48V BL70S-... | G2: 크로스 주행 모터 | H2: 6 | I2: PC | J2: 45254
A3: NIKE ORDER | C3: 45211 | D3: DLS | E3: 10411039_01 | F3: LIFT DRIVE UNIT E60H4+EMT245 ELR 48VDC | G3: LIFT DRIVE UNIT E60H4+EMT245 ELR 48VDC | H3: 6 | I3: PC | J3: 45254
A4: NIKE ORDER | C4: 45211 | D4: DLS | E4: 10764610_01 | F4: CURRENT COLLECTOR, 0815 2P1PH 35A REV... | G4: 커런트 컬렉터 | H4: 30 | I4: PC | J4: 45254
A5: NIKE ORDER | C5: 45211 | D5: DLS | E5: 10567315_01 | F5: BOGIE WHEEL, LFW ABLF EBG OSR_EVO | G5: 메인 통로 주행 휠 | H5: 20 | I5: PC | J5: 45254
A6: NIKE ORDER | C6: 45211 | D6: DLS | E6: 10567316_01 | F6: BOGIE WHEEL, QFW ABLF EBG, OSR_EVO | G6: 크로스 통로 주행 휠 | H6: 20 | I6: PC | J6: 45254
A7: NIKE ORDER | C7: 45212 | D7: DLS | E7: 10412613_02 | F7: CORNER ELEMENT EBG -M, OSR_EVO | G7: Corner element (Corner cover)_Front left side | H7: 2 | I7: PC | J7: 45274
A8: NIKE ORDER | C8: 45212 | D8: DLS | E8: 10412613_04 | F8: CORNER ELEMENT EBG -M, OSR_EVO | G8: Corner element (Corner cover)_Front right side | H8: 2 | I8: PC | J8: 45274
A9: NIKE ORDER | C9: 45212 | D9: DLS | E9: 10412613_03 | F9: CORNER ELEMENT EBG -M, OSR_EVO | G9: Corner element (Corner cover)_Rear left side | H9: 3 | I9: PC | J9: 45274
A10: NIKE ORDER | C10: 45212 | D10: DLS | E10: 10412613_05 | F10: CORNER ELEMENT EBG -M, OSR_EVO | G10: Corner element (Corner cover)_Rear right side | H10: 2 | I10: PC | J10: 45274
A11: NIKE ORDER | C11: 45212 | D11: DLS | E11: 10410230_01 | F11: GEAR MOTOR ELR 350/7.5/3150 24V BL70M... | G11: 메인 주행 휠 모터 | H11: 3 | I11: PC | J11: 45274
A12: NIKE ORDER | C12: 45212 | D12: DLS | E12: 10395200_01 | F12: GEAR MOTOR ELR/11.8 48V BL57AL-48V + ... | G12: 텔레스코프 모터 | H12: 3 | I12: PC | J12: 45274
A13: NIKE ORDER | C13: 45212 | D13: DLS | E13: 10540023_01 | F13: GEAR MOTOR ELR/33/3000 48V BL42YS-48V... | G13: 바리오 센터링 모터 | H13: 3 | I13: PC | J13: 45274
... A16: NIKE ORDER | C16: 45212 | D16: DLS | E16: 10652991_01 | F16: TABLET, KAG ZEBRA ET51 10" RW INKL. R... | G16: SCADA 테블릿 | H16: 2 | I16: PC | J16: 45274
A17: Warranty | D17: DLS | E17: 10412613_02 | F17: CORNER ELEMENT EBG -M, OSR_EVO | G17: Corner element (Corner cover)_Front left side | H17: 3 | I17: PC | J17: 45230
A18: Warranty | D18: DLS | E18: 10412613_04 | F18: CORNER ELEMENT EBG -M, OSR_EVO | G18: Corner element (Corner cover)_Front right side | H18: 3 | I18: PC | J18: 45230
A19: Warranty | D19: DLS | E19: 10412613_03 | F19: CORNER ELEMENT EBG -M, OSR_EVO | G19: Corner element (Corner cover)_Rear left side | H19: 3 | I19: PC | J19: 45230
A20: Warranty | D20: DLS | E20: 10412613_05 | F20: CORNER ELEMENT EBG -M, OSR_EVO | G20: Corner element (Corner cover)_Rear right side | H20: 3 | I20: PC | J20: 45230
A21: Warranty | D21: DLS | E21: 10849086_01 | F21: SCANNER, Cognex, DM280 | G21: 바코드 스캐너 | H21: 1 | I21: PC | J21: 45230
A22: Warranty | D22: DLS | E22: 10764610_01 | F22: CURRENT COLLECTOR, 0815 2P1PH 35A REV... | H22: 20 | I22: PC | J22: 45216
A23: Warranty | D23: DLS | E23: 10764610_01 | F23: CURRENT COLLECTOR, 0815 2P1PH 35A REV... | H23: 72 | I23: PC | J23: 45230
A24: Warranty | D24: DLS | E24: 10411039_01 | F24: LIFT DRIVE UNIT E60H4+EMT245 ELR 48VDC | G24: LIFT DRIVE UNIT E60H4+EMT245 ELR 48VDC / MOTOR2 | H24: 5 | I24: PC | J24: 45268
A25: NIKE ORDER | C25: 발주완료 | D25: 엘림철물 | E25: Unknown | F25: PILZ Safety switch 506334 (506301+506308) | G25: 랙 통로 Door safety switch | H25: 2 | I25: PC | J25: 45293
A26: Warranty | C26: 45243 | D26: DLS | E26: 10609544_02_0001 | F26: ACCESS CONCEPT LZYL=4510 LINKS 1E V2 ... | G26: KNAPP LOCK 장치 | H26: 3 | I26: PC | J26: 45351
A27: Warranty | C27: 45243 | D27: DLS | E27: 10709974_01 | F27: ACCESS POINT, KAG ARUBA AP-504 RW CON… | G27: Network AP | H27: 1 | I27: PC | J27: 45280
A28: Warranty | C28: 45243 | D28: DLS | E28: 10679338_01 | F28: SIDE GUIDE WHEEL COMPENSA EBG -M, OSR… | H28: 4 | I28: PC
A29: Warranty | C29: 45194 | D29: DLS | E29: 10411034_01 | F29: GEAR MOTOR ELR 220/10/3500 48V BL70S-... | G29: 크로스 주행 모터 (모터2) | H29: 10 | I29: PC | J29: 45268
A30: Warranty | D30: DLS | E30: 10416079_01 | F30: CURRENT COLLECTOR, 0815 2P1PH 35A REV... | H30: 12 | I30: PC | J30: 45268
A31: Warranty | D31: DLS | E31: 10328021_02_0017 | F31: Motorized roller NB=900 Int MR -M, ST | G31: 컨베이어 롤러 NB=900mm | H31: 10 | I31: PC | J31: 45268
A32: Warranty | D32: DLS | E32: 10328173_02_0011 | F32: Carrier roller Int NB=900 MR M. CLIPS.. | H32: 10 | I32: PC | J32: 45268
A33: Warranty | C33: 45194 | D33: DLS | E33: 10540023_01 | F33: GEAR MOTOR ELR/33/3000 48V BL42YS-48V... | G33: 바리오 센터링 모터 | H33: 1 | I33: PC
A34: Warranty | C34: 45194 | D34: DLS | E34: 10411039_01 | F34: LIFT DRIVE UNIT E60H4+EMT245 ELR 48VDC | G34: LIFT DRIVE UNIT E60H4+EMT245 ELR 48VDC | H34: 3 | I34: PC
A35: Warranty | C35: 45194 | D35: DLS | E35: 10519144 | F35: INDUCTIVE SENSOR, SICK IMA18-20NE1ZC0K | G35: 셔틀 하부 크로스 레일 감지 | H35: 1 | I35: PC | J35: 45351
A36: Warranty | C36: 45293 | D36: DLS | E36: 10867661 | F36: OPTICAL SENSOR, OYKS950 REFL.LS M. HGA | G36: Position marker sensor | H36: 2 | I36: PC | J36: 45351
A37: NIKE ORDER | C37: 45648 | D37: 밀뱅코리아 | E37: 10849086_01 | F37: SCANNER, Cognex, DM280 | G37: 바코드 스캐너 | H37: 2 | I37: PC | J37: 45315
A38: Warranty | C38: 45293 | D38: DLS | E38: 10849086_01 | F38: SCANNER, Cognex, DM280 | G38: 바코드 스캐너 | H38: 1 | I38: PC | J38: 45351
A39: NIKE ORDER | C39: 견적요청중 | D39: DLS | E39: Unknown | F39: Vario timing belt | G39: 바리오 폭 조정 타이밍 벨트 | H39: 20 | I39: PC
A40: Warranty | C40: 45287 | D40: DLS | E40: 85365019 | F40: INDUCTIVE SENSOR, I18H022 20MM M18 | G40: 셔틀 하부 크로스 레일 감지 | H40: 1 | I40: PC | J40: 45378
A41: Warranty | C41: 45293 | D41: DLS | E41: 10547019_03 | F41: SUPERCAPACITOR EBG V2 -M, OSR_EVO | G41: SEM (셔틀 22번 교체) | H41: 1 | I41: PC | J41: 45351
A42: Warranty | D42: DLS | E42: 10547019_03 | F42: SUPERCAPACITOR EBG V2 -M, OSR_EVO | G42: SEM (셔틀 72번 교체) | H42: 1 | I42: PC
...

Sheet ASRS parts replacement
N1: 0
N2: 1 | O2: 2 | P2: 3 | Q2: 4 | R2: 5 | S2: 6 | T2: 7 | U2: 8 | V2: 9 | W2: 10 | X2: 11 | Y2: 12 | Z2: 13 | AA2: 14 | AB2: 15 | AC2: 16 | AD2: 17 | AE2: 18 | AF2: 19 | AG2: 20 | AH2: 21 | AI2: 22 | AJ2: 23 | AK2: 24 | AL2: 25 | AM2: 26 | AN2: 27 | AO2: 28 | AP2: 29 | AQ2: 30 | AR2: 31 | AS2: 32 | AT2: 33 | AU2: 34 | AV2: 35 | AW2: 36 | AX2: 37 | AY2: 38 | AZ2: 39 | BA2: 40 | BB2: 41 | BC2: 42 | BD2: 43 | BE2: 44 | BF2: 45 | BG2: 46 | BH2: 47 | BI2: 48 | BJ2: 49 | BK2: 50 | BL2: 51 | BM2: 52 | BN2: 53 | BO2: 54 | BP2: 55 | BQ2: 56 | BR2: 57 | BS2: 58 | BT2: 59 | BU2: 60 | BV2: 61 | BW2: 62 | BX2: 63 | BY2: 64 | BZ2: 65 | CA2: 66 | CB2: 67 | CC2: 68 | CD2: 69 | CE2: 70 | CF2: 71 | CG2: 72 | CH2: 73 | CI2: 74 | CJ2: 75 | CK2: 76 | CL2: 77 | CM2: 78 | CN2: 79 | CO2: 80 | CP2: 81 | CQ2: 82 | CR2: 83 | CS2: 84 | CT2: 85 | CU2: 86 | CV2: 87 | CW2: 88 | CX2: 89 | CY2: 90 | CZ2: 91 | DA2: 92 | DB2: 93 | DC2: 94 | DD2: 95 | DE2: 96
L3: =COUNTIF(N3:DC3,N1) -> 1 | M3: Current collector(랙통로) | N3: =COUNTIFS($B:$B,N$2,$C:$C,$M3) -> 7 | O3: =COUNTIFS($B:$B,O$2,$C:$C,$M3) -> 6 | P3: =COUNTIFS($B:$B,P$2,$C:$C,$M3) -> 7 | Q3: =COUNTIFS($B:$B,Q$2,$C:$C,$M3) -> 5 | R3: =COUNTIFS($B:$B,R$2,$C:$C,$M3) -> 2 | S3: =COUNTIFS($B:$B,S$2,$C:$C,$M3) -> 2 | T3: =COUNTIFS($B:$B,T$2,$C:$C,$M3) -> 6 | U3: =COUNTIFS($B:$B,U$2,$C:$C,$M3) -> 3 | ... DE3: =COUNTIFS($B:$B,DE$2,$C:$C,$M3) -> 0
L4: =COUNTIF(N4:DC4,N1) -> 32 | M4: Current collector(크로스) | N4: =COUNTIFS($B:$B,N$2,$C:$C,$M4) -> 1 | O4: =COUNTIFS($B:$B,O$2,$C:$C,$M4) -> 1 | P4: =COUNTIFS($B:$B,P$2,$C:$C,$M4) -> 2 | Q4: =COUNTIFS($B:$B,Q$2,$C:$C,$M4) -> 1 | R4: =COUNTIFS($B:$B,R$2,$C:$C,$M4) -> 1 | S4: =COUNTIFS($B:$B,S$2,$C:$C,$M4) -> 0 | T4: =COUNTIFS($B:$B,T$2,$C:$C,$M4) -> 0 | U4: =COUNTIFS($B:$B,U$2,$C:$C,$M4) -> 1 | ... DE4: =COUNTIFS($B:$B,DE$2,$C:$C,$M4) -> 0
L5: =COUNTIF(N5:DC5,N1) -> 0 | M5: TOTAL | N5: =SUM(N3:N4) -> 8 | O5: =SUM(O3:O4) -> 7 | P5: =SUM(P3:P4) -> 9 | Q5: =SUM(Q3:Q4) -> 6 | R5: =SUM(R3:R4) -> 3 | S5: =SUM(S3:S4) -> 2 | T5: =SUM(T3:T4) -> 6 | U5: =SUM(U3:U4) -> 4 | ... DE5: =SUM(DE3:DE4) -> 0 | DF5: =SUM(N5:DE5) -> 486
A14: Date | B14: Shuttle# | C14: Parts I | D14: Parts II | E14: Parts III | F14: Material Number | G14: Remark | H14: Used days | I14: NEW/USED | J14: Warranty | K14: Warranty 요청 | L14: 세로 막대형1
A15: 46148 | B15: 37 | C15: Current collector(랙통로) | D15: CURRENT COLLECTOR, 0815 2P1PH 35A REV... | E15: 종방향 | F15: =VLOOKUP(D15,Parts!D:N, 11,FALSE) -> 10764610_01 | G15: 불량으로 인한 교체 | H15: =TODAY()-표1[[#This Row],[Date]] -> 5 | I15: NEW
A16: 46146 | B16: 90 | C16: Current collector(랙통로) | D16: CURRENT COLLECTOR, 0815 2P1PH 35A REV... | E16: 종방향 | F16: =VLOOKUP(D16,Parts!D:N, 11,FALSE) -> 10764610_01 | G16: 불량으로 인한 교체 | H16: =TODAY()-표1[[#This Row],[Date]] -> 7 | I16: NEW
A17: 46134 | B17: 53 | C17: Current collector(랙통로) | D17: CURRENT COLLECTOR, 0815 2P1PH 35A REV... | E17: 종방향 | F17: =VLOOKUP(D17,Parts!D:N, 11,FALSE) -> 10764610_01 | G17: 마모로 인한 교체 | H17: =TODAY()-표1[[#This Row],[Date]] -> 19 | I17: NEW
A18: 46134 | B18: 53 | C18: Cover | D18: CORNER ELEMENT EBG -M, OSR_EVO (rear left side) | E18: Corner element (Corner cover)_rear left side | F18: =VLOOKUP(D18,Parts!D:N, 11,FALSE) -> 10412613_02 | G18: 파손으로 교체 | H18: =TODAY()-표1[[#This Row],[Date]] -> 19 | I18: NEW
A19: 46134 | B19: 53 | C19: Wheel | D19: BOGIE WHEEL, LFW ABLF EBG OSR_EVO | E19: 종방향 주행 휠 | F19: =VLOOKUP(D19,Parts!D:N, 11,FALSE) -> 10567315_01 | G19: 마모로 인한 교체 | H19: =TODAY()-표1[[#This Row],[Date]] -> 19 | I19: NEW
A20: 46134 | B20: 53 | C20: Sideguide wheel | D20: SIDE GUIDE V8 EBG -M, OSR_EVO (Front left side, Rear right side) | E20: 2EA | F20: =VLOOKUP(D20,Parts!D:N, 11,FALSE) -> 10907771_02 | G20: 파손으로 4ea 교체 | H20: =TODAY()-표1[[#This Row],[Date]] -> 19 | I20: NEW
A21: 46134 | B21: 53 | C21: Sideguide wheel | D21: SIDE GUIDE V8 EBG -M, OSR_EVO (Front right side, Rear left side) | E21: 2EA | F21: =VLOOKUP(D21,Parts!D:N, 11,FALSE) -> 10907771_03 | G21: 파손으로 4ea 교체 | H21: =TODAY()-표1[[#This Row],[Date]] -> 19 | I21: NEW
A22: 46129 | B22: 51 | C22: Wheel | D22: BOGIE WHEEL, LFW ABLF EBG OSR_EVO | E22: 종방향 주행 휠 | F22: =VLOOKUP(D22,Parts!D:N, 11,FALSE) -> 10567315_01 | G22: 마모로 4EA 교체 | H22: =TODAY()-표1[[#This Row],[Date]] -> 24 | I22: NEW
A23: 46129 | B23: 51 | C23: Sideguide wheel | D23: SIDE GUIDE V8 EBG -M, OSR_EVO (Front left side, Rear right side) | E23: 2EA | F23: =VLOOKUP(D23,Parts!D:N, 11,FALSE) -> 10907771_02 | G23: (PM) 개선품 교체 | H23: =TODAY()-표1[[#This Row],[Date]] -> 24 | I23: NEW
A24: 46129 | B24: 51 | C24: Sideguide wheel | D24: SIDE GUIDE V8 EBG -M, OSR_EVO (Front right side, Rear left side) | E24: 2EA | F24: =VLOOKUP(D24,Parts!D:N, 11,FALSE) -> 10907771_03 | G24: (PM) 개선품 교체 | H24: =TODAY()-표1[[#This Row],[Date]] -> 24 | I24: NEW
A25: 46127 | B25: 66 | C25: Current collector(랙통로) | D25: CURRENT COLLECTOR, 0815 2P1PH 35A REV... | E25: 종방향 | F25: =VLOOKUP(D25,Parts!D:N, 11,FALSE) -> 10764610_01 | G25: 마모로 인한 교체 | H25: =TODAY()-표1[[#This Row],[Date]] -> 26 | I25: NEW
A26: 46125 | B26: 40 | C26: Current collector(랙통로) | D26: CURRENT COLLECTOR, 0815 2P1PH 35A REV... | E26: 종방향 | F26: =VLOOKUP(D26,Parts!D:N, 11,FALSE) -> 10764610_01 | G26: 불량으로 인한 교체 | H26: =TODAY()-표1[[#This Row],[Date]] -> 28 | I26: NEW
... A40: 46104 | B40: 24 | C40: SEM | D40: SUPERCAPACITOR EBG V2 -M, OSR_EVO | E40: 안전 확장 모듈 Safety Extension Module | F40: =VLOOKUP(D40,Parts!D:N, 11,FALSE) -> 10547019_03 | G40: EVOS-0035 error 전원공급 불량으로 교체 | H40: =TODAY()-표1[[#This Row],[Date]] -> 49 | I40: NEW
A41: 46104 | B41: 24 | C41: Current collector(랙통로) | D41: CURRENT COLLECTOR, 0815 2P1PH 35A REV... | E41: 종방향 | F41: =VLOOKUP(D41,Parts!D:N, 11,FALSE) -> 10764610_01 | H41: =TODAY()-표1[[#This Row],[Date]] -> 49 | I41: NEW
A42: 46100 | B42: 57 | C42: Motor | D42: GEAR MOTOR ELRkw/33kw/3000 48V BL42YS-48V... | E42: 바리오 센터링 모터 (모터5) | F42: =VLOOKUP(D42,Parts!D:N, 11,FALSE) -> 10540023_01 | G42: EVOS-0022 Error | H42: =TODAY()-표1[[#This Row],[Date]] -> 53 | I42: NEW
A43: 46099 | B43: 57 | C43: Printed Circuit Board | D43: ASSEMB. PRINTED CIRCUIT BOARD, SHUTTL... Replacement for 10676955_02 | E43: 셔틀 인쇄 회로 기판 | F43: =VLOOKUP(D43,Parts!D:N, 11,FALSE) -> 10676955_08 | G43: EVOS-0022 Error | H43: =TODAY()-표1[[#This Row],[Date]] -> 54 | I43: NEW
A44: 46098 | B44: 59 | C44: Motor | D44: GEAR MOTOR ELR 220kw/10kw/3500 48V BL70S-... | E44: 횡방향 주행 모터 (모터2) | F44: =VLOOKUP(D44,Parts!D:N, 11,FALSE) -> 10411034_01 | G44: 불량(케이블 단선)으로 인한 교체(Motor2 error) | H44: =TODAY()-표1[[#This Row],[Date]] -> 55 | I44: NEW
A45: 46098 | B45: 28 | C45: Current collector(랙통로) | D45: CURRENT COLLECTOR, 0815 2P1PH 35A REV... | E45: 종방향 | F45: =VLOOKUP(D45,Parts!D:N, 11,FALSE) -> 10764610_01 | G45: 불량으로 인한 교체 | H45: =TODAY()-표1[[#This Row],[Date]] -> 55 | I45: NEW
A46: 46097 | B46: 26 | C46: Current collector(랙통로) | D46: CURRENT COLLECTOR PAIR 1 Set | E46: 종방향 | F46: =VLOOKUP(D46,Parts!D:N, 11,FALSE) -> 1 | G46: 마모로 인한 교체 | H46: =TODAY()-표1[[#This Row],[Date]] -> 56 | I46: NEW
A47: 46093 | B47: 29 | C47: Current collector(랙통로) | D47: CURRENT COLLECTOR PAIR 1 Set | E47: 종방향 | F47: =VLOOKUP(D47,Parts!D:N, 11,FALSE) -> 1 | G47: 마모로 인한 교체 | H47: =TODAY()-표1[[#This Row],[Date]] -> 60 | I47: NEW
A48: 46092 | B48: 52 | C48: Current collector(랙통로) | D48: CURRENT COLLECTOR, 0815 2P1PH 35A REV... | E48: 종방향 | F48: =VLOOKUP(D48,Parts!D:N, 11,FALSE) -> 10764610_01 | G48: 파손으로 인한 교체 | H48: =TODAY()-표1[[#This Row],[Date]] -> 61 | I48: NEW
A49: 46091 | B49: 52 | C49: Sideguide wheel | D49: SIDE GUIDE V8 EBG -M, OSR_EVO (Front left side, Rear right side) | E49: 2EA | F49: =VLOOKUP(D49,Parts!D:N, 11,FALSE) -> 10907771_02 | G49: (PM) 개선품 교체 | H49: =TODAY()-표1[[#This Row],[Date]] -> 62 | I49: NEW
A50: 46091 | B50: 52 | C50: Sideguide wheel | D50: SIDE GUIDE V8 EBG -M, OSR_EVO (Front right side, Rear left side) | E50: 2EA | F50: =VLOOKUP(D50,Parts!D:N, 11,FALSE) -> 10907771_03 | G50: (PM) 개선품 교체 | H50: =TODAY()-표1[[#This Row],[Date]] -> 62 | I50: NEW
A51: 46091 | B51: 52 | C51: Current collector(랙통로) | D51: CURRENT COLLECTOR PAIR 1 Set | E51: 횡방향 | F51: =VLOOKUP(D51,Parts!D:N, 11,FALSE) -> 1 | G51: (PM)마모로 인한 교체 | H51: =TODAY()-표1[[#This Row],[Date]] -> 62 | I51: NEW
A52: 46091 | B52: 52 | C52: Current collector(랙통로) | D52: CURRENT COLLECTOR PAIR 1 Set | E52: 종방향 | F52: =VLOOKUP(D52,Parts!D:N, 11,FALSE) -> 1 | G52: (PM)마모로 인한 교체 | H52: =TODAY()-표1[[#This Row],[Date]] -> 62 | I52: NEW
A53: 46090 | C53: RFID | D53: MOUNTING KIT RAL1016 RFID R_KG -M, OS… | E53: RFID 트랜스폰더_HB-B 크로스구간(노란색 브라켓포함) 2EA | F53: =VLOOKUP(D53,Parts!D:N, 11,FALSE) -> 10428896_01_0002 | G53: 3통로 16Lv C01,C03 파손으로 교체 | H53: =TODAY()-표1[[#This Row],[Date]] -> 63 | I53: NEW
A54: 46089 | B54: 50 | C54: Current collector(랙통로) | D54: CURRENT COLLECTOR PAIR 1 Set | E54: 횡방향 | F54: =VLOOKUP(D54,Parts!D:N, 11,FALSE) -> 1 | G54: (PM)마모로 인한 교체 | H54: =TODAY()-표1[[#This Row],[Date]] -> 64 | I54: NEW
A55: 46089 | B55: 50 | C55: Current collector(랙통로) | D55: CURRENT COLLECTOR PAIR 1 Set | E55: 종방향 | F55: =VLOOKUP(D55,Parts!D:N, 11,FALSE) -> 1 | G55: (PM)마모로 인한 교체 | H55: =TODAY()-표1[[#This Row],[Date]] -> 64 | I55: NEW
A56: 46087 | B56: 50 | C56: Sideguide wheel | D56: SIDE GUIDE V8 EBG -M, OSR_EVO (Front left side, Rear right side) | E56: 2EA | F56: =VLOOKUP(D56,Parts!D:N, 11,FALSE) -> 10907771_02 | G56: (PM)파손으로 4EA 교체 | H56: =TODAY()-표1[[#This Row],[Date]] -> 66 | I56: NEW
A57: 46087 | B57: 50 | C57: Sideguide wheel | D57: SIDE GUIDE V8 EBG -M, OSR_EVO (Front right side, Rear left side) | E57: 2EA | F57: =VLOOKUP(D57,Parts!D:N, 11,FALSE) -> 10907771_03 | G57: (PM)파손으로 4EA 교체 | H57: =TODAY()-표1[[#This Row],[Date]] -> 66 | I57: NEW
A58: 46086 | B58: 49 | C58: Wheel | D58: BOGIE WHEEL, LFW ABLF EBG OSR_EVO | E58: 종방향 주행 휠 | F58: =VLOOKUP(D58,Parts!D:N, 11,FALSE) -> 10567315_01 | G58: (PM)마모로 4EA 교체 | H58: =TODAY()-표1[[#This Row],[Date]] -> 67 | I58: NEW
A59: 46086 | B59: 49 | C59: Current collector(랙통로) | D59: CURRENT COLLECTOR, 0815 2P1PH 35A REV... | E59: 종방향 | F59: =VLOOKUP(D59,Parts!D:N, 11,FALSE) -> 10764610_01 | G59: (PM)마모,유닛 전체 교체(Knapp) | H59: =TODAY()-표1[[#This Row],[Date]] -> 67 | I59: NEW
A60: 46086 | B60: 92 | C60: Sideguide wheel | D60: SIDE GUIDE V8 EBG -M, OSR_EVO (Front left side, Rear right side) | E60: Front Left 1EA | F60: =VLOOKUP(D60,Parts!D:N, 11,FALSE) -> 10907771_02 | G60: 파손으로 인한 교체 | H60: =TODAY()-표1[[#This Row],[Date]] -> 67 | I60: NEW
A61: 46086 | B61: 45 | C61: Current collector(랙통로) | D61: CURRENT COLLECTOR PAIR 1 Set | E61: 종방향 | F61: =VLOOKUP(D61,Parts!D:N, 11,FALSE) -> 1 | G61: 마모로 인한 교체 | H61: =TODAY()-표1[[#This Row],[Date]] -> 67 | I61: NEW
...

Sheet 임시) DLS PM 대여 항목
A1: 반출 날짜 | E1: Part # | F1: 수량 | G1: 반납
A2: 46087 | B2: Motor-Prot. Circuit Breaker-400V-2.5A… | C2: GV2ME08 | D2: ASRS | E2: 10217147 | F2: 1 | G2: X
A3: 46087 | B3: POWER SUPPLY UNIT, PRO MAX 480W 48V 20A | C3: 480W, 48V 파워서플라이 | D3: ASRS | E3: 10623481 | F3: 1 | G3: O
A4: 46090 | B4: POWER SUPPLY UNIT, PRO MAX 480W 48V 20A | C4: GV2ME08 | D4: ASRS | E4: 10217147 | F4: 1 | G4: X
A5: 46090 | B5: Motor-Prot. Circuit Breaker-400V-2.5A… | C5: 480W, 48V 파워서플라이 | D5: ASRS | E5: 10623481 | F5: 1 | G5: X
A6: 46114 | C6: 리프트 휠 12EA (종류 및 No. 확인 필요) | F6: 12 | H6: 정지용님

Sheet Monthly
A1: Month | B1: Category | C1: TotalQty | D1: FulfilledQty | E1: NotFulfilledQty | F1: FulfillmentRate
A2: 45959 | B2: ASRS | C2: 332 | D2: =C2-E2 -> 294 | E2: 38 | F2: =IF(C2>0,D2/C2,0) -> 0.88554217
A3: 45959 | B3: Conveyor | C3: 637 | D3: =C3-E3 -> 471 | E3: 166 | F3: =IF(C3>0,D3/C3,0) -> 0.73940345
A4: 45959 | B4: Utility | C4: 179 | D4: =C4-E4 -> 179 | E4: 0 | F4: =IF(C4>0,D4/C4,0) -> 1
A5: 45959 | B5: Electrical | C5: 71 | D5: =C5-E5 -> 71 | E5: 0 | F5: =IF(C5>0,D5/C5,0) -> 1
A6: 45991 | B6: ASRS | C6: 332 | D6: =C6-E6 -> 294 | E6: 38 | F6: =IF(C6>0,D6/C6,0) -> 0.88554217
A7: 45991 | B7: Conveyor | C7: 668 | D7: =C7-E7 -> 560 | E7: 108 | F7: =IF(C7>0,D7/C7,0) -> 0.83832335
A8: 45991 | B8: Utility | C8: 179 | D8: =C8-E8 -> 179 | E8: 0 | F8: =IF(C8>0,D8/C8,0) -> 1
A9: 45991 | B9: Electrical | C9: 71 | D9: =C9-E9 -> 71 | E9: 0 | F9: =IF(C9>0,D9/C9,0) -> 1
A10: 45992 | B10: ASRS | C10: 344 | D10: =C10-E10 -> 312 | E10: 32 | F10: =IF(C10>0,D10/C10,0) -> 0.90697674
A11: 45992 | B11: Conveyor | C11: 671 | D11: =C11-E11 -> 611 | E11: 60 | F11: =IF(C11>0,D11/C11,0) -> 0.91058122
A12: 45992 | B12: Utility | C12: 192 | D12: =C12-E12 -> 189 | E12: 3 | F12: =IF(C12>0,D12/C12,0) -> 0.984375
A13: 45992 | B13: Electrical | C13: 71 | D13: =C13-E13 -> 71 | E13: 0 | F13: =IF(C13>0,D13/C13,0) -> 1
... A25: 46082 | B25: Electrical | C25: 71 | D25: =C25-E25 -> 71 | E25: 0 | F25: =IF(C25>0,D25/C25,0) -> 1
A26: 46113 | B26: ASRS | D26: =C26-E26 -> 0 | F26: =IF(C26>0,D26/C26,0) -> 0
A27: 46113 | B27: Conveyor | D27: =C27-E27 -> 0 | F27: =IF(C27>0,D27/C27,0) -> 0
A28: 46113 | B28: Utility | D28: =C28-E28 -> 0 | F28: =IF(C28>0,D28/C28,0) -> 0
A29: 46113 | B29: Electrical | D29: =C29-E29 -> 0 | F29: =IF(C29>0,D29/C29,0) -> 0
A30: 46143 | B30: ASRS | D30: =C30-E30 -> 0
A31: 46143 | B31: Conveyor | D31: =C31-E31 -> 0
A32: 46143 | B32: Utility | D32: =C32-E32 -> 0
A33: 46143 | B33: Electrical | D33: =C33-E33 -> 0

Sheet 대응자료
G1: 1717
B2: 구분 | C2: PO amount | D2: Part Name(1) | E2: Order number | F2: Unit price (EUR) | G2: Unit price (KRW) | H2: Purchase date (Receive date) | I2: Purchase Q'ty | J2: Used Q'ty (~2024.12) | K2: Balance Q'ty (~2024.12) | L2: 잔존 금액 | M2: Used Q'ty (2023.08 ~ Current) | N2: Balance Q'ty (Current) | O2: 잔존금액 | P2: Remark
B3: 납품확인서_NIKE(KR00022)_KNAPP Spare parts 5종 | C3: 29100000 | D3: GEAR MOTOR ELR 220kw/10kw/3500 48V BL70S-... | E3: 10411034_01 | F3: 572.63 | G3: =F3*$G$1 -> 983205.71 | H3: 2023.11.24 | I3: 6 | J3: =COUNTIF('ASRS parts replacement'!F417:F10013,대응자료!E3) -> 8 | K3: =I3-J3 -> -2 | L3: 0 | M3: =COUNTIF('ASRS parts replacement'!F:F,대응자료!E3) -> 15 | N3: =VLOOKUP(D3,Parts!D:H,5,FALSE) -> 9 | O3: =N3*G3 -> 8848851.4 | P3: 안전재고 보유 사유
D4: LIFT DRIVE UNIT E60H4+EMT245 ELR 48VDC | E4: 10411039_01 | F4: 691.97 | G4: =F4*$G$1 -> 1188112.5 | I4: 6 | J4: =COUNTIF('ASRS parts replacement'!F418:F10014,대응자료!E4) -> 5 | K4: =I4-J4 -> 1 | L4: =G4*K4 -> 1188112.5 | M4: =COUNTIF('ASRS parts replacement'!F:F,대응자료!E4) -> 9 | N4: =VLOOKUP(D4,Parts!D:H,5,FALSE) -> 7 | O4: =N4*G4 -> 8316787.4 | P4: Vendor로부터 구매하여 장기 리드타임 부품(약 3개월)
D5: CURRENT COLLECTOR, 0815 2P1PH 35A REV... | E5: 10764610_01 | F5: 170.83 | G5: =F5*$G$1 -> 293315.11 | I5: 30 | J5: =COUNTIF('ASRS parts replacement'!F419:F10015,대응자료!E5) -> 235 | K5: =I5-J5 -> -205 | L5: 0 | M5: =COUNTIF('ASRS parts replacement'!F:F,대응자료!E5) -> 304 | N5: =VLOOKUP(D5,Parts!D:H,5,FALSE) -> 104 | O5: =N5*G5 -> 30504771 | P5: 고장 시 즉각 교체 안되면 다운타임 리스크 있음
D6: BOGIE WHEEL, LFW ABLF EBG OSR_EVO | E6: 10567315_01 | F6: 64.6 | G6: =F6*$G$1 -> 110918.2 | I6: 20 | J6: =COUNTIF('ASRS parts replacement'!F420:F10016,대응자료!E6) -> 3 | K6: =I6-J6 -> 17 | L6: =G6*K6 -> 1885609.4 | M6: =COUNTIF('ASRS parts replacement'!F:F,대응자료!E6) -> 20 | N6: =VLOOKUP(D6,Parts!D:H,5,FALSE) -> 61 | O6: =N6*G6 -> 6766010.2 | P6: 운영 안정성 유지를 위한 관리 대상 재고
D7: BOGIE WHEEL, QFW ABLF EBG, OSR_EVO | E7: 10567316_01 | F7: 53.39 | G7: =F7*$G$1 -> 91670.63 | I7: 20 | J7: =COUNTIF('ASRS parts replacement'!F421:F10017,대응자료!E7) -> 21 | K7: =I7-J7 -> -1 | L7: 0 | M7: =COUNTIF('ASRS parts replacement'!F:F,대응자료!E7) -> 45 | N7: =VLOOKUP(D7,Parts!D:H,5,FALSE) -> 146 | O7: =N7*G7 -> 13383912 | P7: 現 안전재고 로직: 전년도 월 평균 사용량 * 6(주문개월수) * 2(2대분), Defualt:1ea/2ea
B8: 납품확인서_KNAPP Spare parts 10종 구입 件 | C8: 42000000 | D8: CORNER ELEMENT EBG -M, OSR_EVO (rear left side) | E8: 10412613_02 | F8: 111.28 | G8: =F8*$G$1 -> 191067.76 | H8: 2023.12.14 | I8: 2 | J8: =COUNTIF('ASRS parts replacement'!F407:F10003,대응자료!E8) -> 0 | K8: =I8-J8 -> 2 | L8: =G8*K8 -> 382135.52 | M8: =COUNTIF('ASRS parts replacement'!F:F,대응자료!E8) -> 1 | N8: =VLOOKUP(D8,Parts!D:H,5,FALSE) -> 5 | O8: =N8*G8 -> 955338.8
D9: CORNER ELEMENT EBG -M, OSR_EVO (rear right side) | E9: 10412613_03 | F9: 110.4 | G9: =F9*$G$1 -> 189556.8 | I9: 3 | J9: =COUNTIF('ASRS parts replacement'!F408:F10004,대응자료!E9) -> 0 | K9: =I9-J9 -> 3 | L9: =G9*K9 -> 568670.4 | M9: =COUNTIF('ASRS parts replacement'!F:F,대응자료!E9) -> 3 | N9: =VLOOKUP(D9,Parts!D:H,5,FALSE) -> 7 | O9: =N9*G9 -> 1326897.6
D10: CORNER ELEMENT EBG -M, OSR_EVO (front right side) | E10: 10412613_04 | F10: 111.28 | G10: =F10*$G$1 -> 191067.76 | I10: 2 | J10: =COUNTIF('ASRS parts replacement'!F409:F10005,대응자료!E10) -> 0 | K10: =I10-J10 -> 2 | L10: =G10*K10 -> 382135.52 | M10: =COUNTIF('ASRS parts replacement'!F:F,대응자료!E10) -> 1 | N10: =VLOOKUP(D10,Parts!D:H,5,FALSE) -> 7 | O10: =N10*G10 -> 1337474.3
D11: CORNER ELEMENT EBG -M, OSR_EVO (front left side) | E11: 10412613_05 | F11: 114.52 | G11: =F11*$G$1 -> 196630.84 | I11: 2 | J11: =COUNTIF('ASRS parts replacement'!F410:F10006,대응자료!E11) -> 0 | K11: =I11-J11 -> 2 | L11: =G11*K11 -> 393261.68 | M11: =COUNTIF('ASRS parts replacement'!F:F,대응자료!E11) -> 0 | N11: =VLOOKUP(D11,Parts!D:H,5,FALSE) -> 6 | O11: =N11*G11 -> 1179785
D12: GEAR MOTOR ELR 350kw/7.5kw/3150 24V BL70M... | E12: 10410230_01 | F12: 668.55 | G12: =F12*$G$1 -> 1147900.3 | I12: 3 | J12: =COUNTIF('ASRS parts replacement'!F411:F10007,대응자료!E12) -> 1 | K12: =I12-J12 -> 2 | L12: =G12*K12 -> 2295800.7 | M12: =COUNTIF('ASRS parts replacement'!F:F,대응자료!E12) -> 1 | N12: =VLOOKUP(D12,Parts!D:H,5,FALSE) -> 7 | O12: =N12*G12 -> 8035302.4
D13: GEAR MOTOR ELRkw/11.8 48V BL57AL-48V + ... | E13: 10395200_01 | F13: 458.11 | G13: =F13*$G$1 -> 786574.87 | I13: 3 | J13: =COUNTIF('ASRS parts replacement'!F412:F10008,대응자료!E13) -> 0 | K13: =I13-J13 -> 3 | L13: =G13*K13 -> 2359724.6 | M13: =COUNTIF('ASRS parts replacement'!F:F,대응자료!E13) -> 0 | N13: =VLOOKUP(D13,Parts!D:H,5,FALSE) -> 9 | O13: =N13*G13 -> 7079173.8
D14: GEAR MOTOR ELRkw/33kw/3000 48V BL42YS-48V... | E14: 10540023_01 | F14: 555.82 | G14: =F14*$G$1 -> 954342.94 | I14: 3 | J14: =COUNTIF('ASRS parts replacement'!F413:F10009,대응자료!E14) -> 1 | K14: =I14-J14 -> 2 | L14: =G14*K14 -> 1908685.9 | M14: =COUNTIF('ASRS parts replacement'!F:F,대응자료!E14) -> 2 | N14: =VLOOKUP(D14,Parts!D:H,5,FALSE) -> 8 | O14: =N14*G14 -> 7634743.5
D15: SHAFT COUPLING ROTEX GS12 COMPACT | E15: 10537096_01 | F15: 25.99 | G15: =F15*$G$1 -> 44624.83 | I15: 30 | J15: =COUNTIF('ASRS parts replacement'!F414:F10010,대응자료!E15) -> 0 | K15: =I15-J15 -> 30 | L15: =G15*K15 -> 1338744.9 | M15: =COUNTIF('ASRS parts replacement'!F:F,대응자료!E15) -> 1 | N15: =VLOOKUP(D15,Parts!D:H,5,FALSE) -> 28 | O15: =N15*G15 -> 1249495.2
D16: ASSEMB. PRINTED CIRCUIT BOARD, SHUTTL... Replacement for 10676955_02 | E16: 10676955_08 | F16: 1059.9 | G16: =F16*$G$1 -> 1819848.3 | I16: 5 | J16: =COUNTIF('ASRS parts replacement'!F415:F10011,대응자료!E16) -> 2 | K16: =I16-J16 -> 3 | L16: =G16*K16 -> 5459544.9 | M16: =COUNTIF('ASRS parts replacement'!F:F,대응자료!E16) -> 4 | N16: =VLOOKUP(D16,Parts!D:H,5,FALSE) -> 6 | O16: =N16*G16 -> 10919090
D17: TABLET, KAG ZEBRA ET51 10" RW INKL. R.. | E17: 10652991_01 | F17: 3155.27 | G17: =F17*$G$1 -> 5417598.6 | I17: 2 | J17: =COUNTIF('ASRS parts replacement'!F416:F10012,대응자료!E17) -> 2 | K17: =I17-J17 -> 0 | L17: =G17*K17 -> 0 | M17: =COUNTIF('ASRS parts replacement'!F:F,대응자료!E17) -> 2 | N17: =VLOOKUP(D17,Parts!D:H,5,FALSE) -> 1 | O17: =N17*G17 -> 5417598.6
B18: 납품확인서_KNAPP Spare parts 구입 件 | C18: 8200000 | D18: ACCESS CONCEPT LZYL=4510 LINKS 1E V2 ... | E18: 10609544_02_0001 | F18: 516.15 | G18: =F18*$G$1 -> 886229.55 | H18: 2024.02.16 | I18: 5 | J18: =COUNTIF('ASRS parts replacement'!F406:F10002,대응자료!E18) -> 10 | K18: =I18-J18 -> -5 | L18: 0 | M18: =COUNTIF('ASRS parts replacement'!F:F,대응자료!E18) -> 10 | N18: =VLOOKUP(D18,Parts!D:H,5,FALSE) -> 10 | O18: =N18*G18 -> 8862295.5
B19: 납품확인서_KNAPP Spare parts 15종 구입 件 | C19: 42000000 | D19: OPTICAL SENSOR, OYKS950 REFL.LS M. HGA Replacement for 10409305 | E19: 10867661 | F19: 93 | G19: =F19*$G$1 -> 159681 | H19: 2024.02.16 | I19: 10 | J19: =COUNTIF('ASRS parts replacement'!F425:F10021,대응자료!E19) -> 10 | K19: =I19-J19 -> 0 | L19: =G19*K19 -> 0 | M19: =COUNTIF('ASRS parts replacement'!F:F,대응자료!E19) -> 26 | N19: =VLOOKUP(D19,Parts!D:H,5,FALSE) -> 88 | O19: =N19*G19 -> 14051928
D20: INDUCTIVE SENSOR, I18H022 20MM M18 | E20: 10409303 | F20: 51.66 | G20: =F20*$G$1 -> 88700.22 | I20: 10 | J20: =COUNTIF('ASRS parts replacement'!F426:F10022,대응자료!E20) -> 2 | K20: =I20-J20 -> 8 | L20: =G20*K20 -> 709601.76 | M20: =COUNTIF('ASRS parts replacement'!F:F,대응자료!E20) -> 8 | N20: =VLOOKUP(D20,Parts!D:H,5,FALSE) -> 10 | O20: =N20*G20 -> 887002.2
D21: INDUCTIVE SENSOR, SICK IMA18-20NE1ZC0K | E21: 10519144 | F21: 289.48 | G21: =F21*$G$1 -> 497037.16 | I21: 10 | J21: =COUNTIF('ASRS parts replacement'!F427:F10023,대응자료!E21) -> 1 | K21: =I21-J21 -> 9 | L21: =G21*K21 -> 4473334.4 | M21: =COUNTIF('ASRS parts replacement'!F:F,대응자료!E21) -> 3 | N21: =VLOOKUP(D21,Parts!D:H,5,FALSE) -> 16 | O21: =N21*G21 -> 7952594.6
D22: HEX.NUT, EN1661 M6-8-ZP-SPERR | E22: 10200757 | F22: 0.2 | G22: =F22*$G$1 -> 343.4 | H22: 2024.02.29 | I22: 100 | J22: =COUNTIF('ASRS parts replacement'!F428:F10024,대응자료!E22) -> 0 | K22: =I22-J22 -> 100 | L22: =G22*K22 -> 34340 | M22: =COUNTIF('ASRS parts replacement'!F:F,대응자료!E22) -> 0 | N22: 100 | O22: =N22*G22 -> 34340
D23: POWER SUPPLY UNIT, TDR-960-24V 40A | E23: 10446264 | F23: 255.47 | G23: =F23*$G$1 -> 438641.99 | I23: 3 | J23: =COUNTIF('ASRS parts replacement'!F429:F10025,대응자료!E23) -> 0 | K23: =I23-J23 -> 3 | L23: =G23*K23 -> 1315926 | M23: =COUNTIF('ASRS parts replacement'!F:F,대응자료!E23) -> 1 | N23: =VLOOKUP(D23,Parts!D:H,5,FALSE) -> 3 | O23: =N23*G23 -> 1315926
D24: POWER SUPPLY UNIT, TDR-960-48V 20A | E24: 10218312 | F24: 255.47 | G24: =F24*$G$1 -> 438641.99 | I24: 3 | J24: =COUNTIF('ASRS parts replacement'!F430:F10026,대응자료!E24) -> 0 | K24: =I24-J24 -> 3 | L24: =G24*K24 -> 1315926 | M24: =COUNTIF('ASRS parts replacement'!F:F,대응자료!E24) -> 0 | N24: =VLOOKUP(D24,Parts!D:H,5,FALSE) -> 4 | O24: =N24*G24 -> 1754568
D25: ACCESS CONCEPT LZYL=4510 LINKS 1E V2 ... | E25: 10609544_02_0001 | F25: 516.15 | G25: =F25*$G$1 -> 886229.55 | I25: 3 | J25: =COUNTIF('ASRS parts replacement'!F431:F10027,대응자료!E25) -> 8 | K25: =I25-J25 -> -5 | L25: 0 | M25: =COUNTIF('ASRS parts replacement'!F:F,대응자료!E25) -> 10 | N25: =VLOOKUP(D25,Parts!D:H,5,FALSE) -> 10 | O25: =N25*G25 -> 8862295.5
D26: ACCESS CONCEPT EMERGENCY E -KPL, K_LOCK | E26: 10505322_01 | F26: 405.55 | G26: =F26*$G$1 -> 696329.35 | I26: 2 | J26: =COUNTIF('ASRS parts replacement'!F432:F10028,대응자료!E26) -> 0 | K26: =I26-J26 -> 2 | L26: =G26*K26 -> 1392658.7 | M26: =COUNTIF('ASRS parts replacement'!F:F,대응자료!E26) -> 0 | N26: =VLOOKUP(D26,Parts!D:H,5,FALSE) -> 5 | O26: =N26*G26 -> 3481646.8
D27: CHAIN TELL1490 TEL. -M, OSR_EVO | E27: 10395761_01_0016 | F27: 150.43 | G27: =F27*$G$1 -> 258288.31 | I27: 5 | J27: =COUNTIF('ASRS parts replacement'!F433:F10029,대응자료!E27) -> 0 | K27: =I27-J27 -> 5 | L27: =G27*K27 -> 1291441.6 | M27: =COUNTIF('ASRS parts replacement'!F:F,대응자료!E27) -> 0 | N27: =VLOOKUP(D27,Parts!D:H,5,FALSE) -> 12 | O27: =N27*G27 -> 3099459.7
D28: Door safety switch, PILZ 506334 (506301+506308) | E28: 10217650 | F28: 121.08 | G28: =F28*$G$1 -> 207894.36 | I28: 10 | J28: =COUNTIF('ASRS parts replacement'!F434:F10030,대응자료!E28) -> 1 | K28: =I28-J28 -> 9 | L28: =G28*K28 -> 1871049.2 | M28: =COUNTIF('ASRS parts replacement'!F:F,대응자료!E28) -> 3 | N28: =VLOOKUP(D28,Parts!D:H,5,FALSE) -> 12 | O28: =N28*G28 -> 2494732.3
D29: CURRENT COLLECTOR, 0815 2P1PH 35A REV... | E29: 10764610_01 | F29: 170.83 | G29: =F29*$G$1 -> 293315.11 | I29: 30 | J29: =COUNTIF('ASRS parts replacement'!F435:F10031,대응자료!E29) -> 227 | K29: =I29-J29 -> -197 | L29: 0 | M29: =COUNTIF('ASRS parts replacement'!F:F,대응자료!E29) -> 304 | N29: =VLOOKUP(D29,Parts!D:H,5,FALSE) -> 104 | O29: =N29*G29 -> 30504771
D30: Sideguide wheel_Vibration buffer | E30: 10634710_01 | F30: 0.25 | G30: =F30*$G$1 -> 429.25 | I30: 100 | J30: =COUNTIF('ASRS parts replacement'!F436:F10032,대응자료!E30) -> 0 | K30: =I30-J30 -> 100 | L30: =G30*K30 -> 42925 | M30: =COUNTIF('ASRS parts replacement'!F:F,대응자료!E30) -> 0 | N30: =VLOOKUP(D30,Parts!D:H,5,FALSE) -> 70 | O30: =N30*G30 -> 30047.5
D31: SIDE GUIDE WHEEL, COMPENSA EBG, OSR_EVO | E31: 10679338_01 | F31: 4.12 | G31: =F31*$G$1 -> 7074.04 | I31: 100 | J31: =COUNTIF('ASRS parts replacement'!F437:F10033,대응자료!E31) -> 0 | K31: =I31-J31 -> 100 | L31: =G31*K31 -> 707404 | M31: =COUNTIF('ASRS parts replacement'!F:F,대응자료!E31) -> 0 | N31: =VLOOKUP(D31,Parts!D:H,5,FALSE) -> 100 | O31: =N31*G31 -> 707404
D32: Sideguide wheel_Bracket (Front left side, rear right side | E32: 10611156_02 | F32: 9.64 | G32: =F32*$G$1 -> 16551.88 | I32: 40 | J32: =COUNTIF('ASRS parts replacement'!F438:F10034,대응자료!E32) -> 14 | K32: =I32-J32 -> 26 | L32: =G32*K32 -> 430348.88 | M32: =COUNTIF('ASRS parts replacement'!F:F,대응자료!E32) -> 16 | N32: =VLOOKUP(D32,Parts!D:H,5,FALSE) -> 26 | O32: =N32*G32 -> 430348.88
D33: Sideguide wheel_Bracket (Front right side, Rear left side | E33: 10611156_03 | F33: 9.64 | G33: =F33*$G$1 -> 16551.88 | I33: 40 | J33: =COUNTIF('ASRS parts replacement'!F439:F10035,대응자료!E33) -> 29 | K33: =I33-J33 -> 11 | L33: =G33*K33 -> 182070.68 | M33: =COUNTIF('ASRS parts replacement'!F:F,대응자료!E33) -> 32 | N33: =VLOOKUP(D33,Parts!D:H,5,FALSE) -> 11 | O33: =N33*G33 -> 182070.68
B34: 납품확인서_KNAPP Spare parts 2종 구입 件 | C34: 2690000 | D34: INCREMENTAL ENCODER, DBS36E-BBAP00S43 | E34: 10408341 | F34: 104.2 | G34: =F34*$G$1 -> 178911.4 | H34: 2024.03.27 | I34: 4 | J34: =COUNTIF('ASRS parts replacement'!F422:F10018,대응자료!E34) -> 4 | K34: =I34-J34 -> 0 | L34: =G34*K34 -> 0 | M34: =COUNTIF('ASRS parts replacement'!F:F,대응자료!E34) -> 5 | N34: =VLOOKUP(D34,Parts!D:H,5,FALSE) -> 8 | O34: =N34*G34 -> 1431291.2
D35: STEPPER MOTOR HSY223-F06C + PX28S-16,... | E35: 10395201_01 | F35: 97.2 | G35: =F35*$G$1 -> 166892.4 | I35: 4 | J35: =COUNTIF('ASRS parts replacement'!F423:F10019,대응자료!E35) -> 5 | K35: =I35-J35 -> -1 | L35: 0 | M35: =COUNTIF('ASRS parts replacement'!F:F,대응자료!E35) -> 5 | N35: =VLOOKUP(D35,Parts!D:H,5,FALSE) -> 19 | O35: =N35*G35 -> 3170955.6
B36: 납품확인서_KNAPP Spare parts 1종 구입 件 | C36: 1680000 | D36: RFID READER, IQT1-FP-R4-V1 | E36: 10404892 | F36: 258.19 | G36: =F36*$G$1 -> 443312.23 | H36: 2024.04.25 | I36: 2 | J36: =COUNTIF('ASRS parts replacement'!F424:F10020,대응자료!E36) -> 8 | K36: =I36-J36 -> -6 | L36: 0 | M36: =COUNTIF('ASRS parts replacement'!F:F,대응자료!E36) -> 12 | N36: =VLOOKUP(D36,Parts!D:H,5,FALSE) -> 4 | O36: =N36*G36 -> 1773248.9
L37: =SUM(L3:L36) -> 31929452 | O37: =SUM(O3:O36) -> 2.0398216e+08

Sheet Sheet1
N1: 1712
B2: 구분 | C2: Part Name(1) | D2: Order number | E2: 설치설비 | F2: 설치갯수 | G2: 현재재고 | H2: 안전재고 | I2: 안전재고 충족현황 | J2: 보관 위치 | K2: Supplier | L2: 제조사 | M2: Unit price (EUR) | N2: Unit price (KRW) | O2: Purchase date (Receive date) | P2: Purchase Q'ty | Q2: Used Q'ty (2023.08~)
B3: 납품확인서_KNAPP Spare parts 구입 件 | C3: ACCESS CONCEPT LZYL=4510 LINKS 1E V2 ... | D3: 10609544_02_0001 | E3: OSR Rack | F3: 94 | G3: 10 | H3: =_xlfn.LET( _xlpm.orderNum,#REF!, _xlpm.usedCount, COUNTIFS( 'ASRS parts replacement'!F:F, _xlpm.orderNum, 'ASRS parts replacement'!A:A, ">=2025-01-01", 'ASRS parts replacement'!A:A, "<=2025-12-31"), IF(_xlpm.usedCount=0, 2, MAX(2, _xlpm.usedCount/12*6*2)) ) -> 2 | I3: =IF(G3<H3,"X","O") -> O | J3: 124 | M3: 516.15 | N3: =M3*$N$1 -> 883648.8 | O3: 2024.02.16 | P3: 5 | Q3: =COUNTIF('ASRS parts replacement'!F:F,D3) -> 10
B4: 납품확인서_KNAPP Spare parts 10종 구입 件 | C4: CORNER ELEMENT EBG -M, OSR_EVO (rear left side) | D4: 10412613_02 | E4: OSR Shuttle | F4: 90 | G4: 5 | H4: =_xlfn.LET( _xlpm.orderNum,#REF!, _xlpm.usedCount, COUNTIFS( 'ASRS parts replacement'!F:F, _xlpm.orderNum, 'ASRS parts replacement'!A:A, ">=2025-01-01", 'ASRS parts replacement'!A:A, "<=2025-12-31"), IF(_xlpm.usedCount=0, 2, MAX(2, _xlpm.usedCount/12*6*2)) ) -> 2 | I4: =IF(G4<H4,"X","O") -> O | J4: 205 | K4: KNAPP | M4: 111.28 | N4: =M4*$N$1 -> 190511.36 | O4: 2023.12.14 | P4: 2 | Q4: =COUNTIF('ASRS parts replacement'!F:F,D4) -> 1
C5: CORNER ELEMENT EBG -M, OSR_EVO (rear right side) | D5: 10412613_03 | E5: OSR Shuttle | F5: 90 | G5: 7 | H5: =_xlfn.LET( _xlpm.orderNum,#REF!, _xlpm.usedCount, COUNTIFS( 'ASRS parts replacement'!F:F, _xlpm.orderNum, 'ASRS parts replacement'!A:A, ">=2025-01-01", 'ASRS parts replacement'!A:A, "<=2025-12-31"), IF(_xlpm.usedCount=0, 2, MAX(2, _xlpm.usedCount/12*6*2)) ) -> 2 | I5: =IF(G5<H5,"X","O") -> O | J5: 204 | K5: KNAPP | M5: 110.4 | N5: =M5*$N$1 -> 189004.8 | P5: 3 | Q5: =COUNTIF('ASRS parts replacement'!F:F,D5) -> 3
C6: CORNER ELEMENT EBG -M, OSR_EVO (front right side) | D6: 10412613_04 | E6: OSR Shuttle | F6: 90 | G6: 7 | H6: =_xlfn.LET( _xlpm.orderNum,#REF!, _xlpm.usedCount, COUNTIFS( 'ASRS parts replacement'!F:F, _xlpm.orderNum, 'ASRS parts replacement'!A:A, ">=2025-01-01", 'ASRS parts replacement'!A:A, "<=2025-12-31"), IF(_xlpm.usedCount=0, 2, MAX(2, _xlpm.usedCount/12*6*2)) ) -> 2 | I6: =IF(G6<H6,"X","O") -> O | J6: 205 | K6: KNAPP | M6: 111.28 | N6: =M6*$N$1 -> 190511.36 | P6: 2 | Q6: =COUNTIF('ASRS parts replacement'!F:F,D6) -> 1
C7: CORNER ELEMENT EBG -M, OSR_EVO (front left side) | D7: 10412613_05 | E7: OSR Shuttle | F7: 90 | G7: 6 | H7: =_xlfn.LET( _xlpm.orderNum,#REF!, _xlpm.usedCount, COUNTIFS( 'ASRS parts replacement'!F:F, _xlpm.orderNum, 'ASRS parts replacement'!A:A, ">=2025-01-01", 'ASRS parts replacement'!A:A, "<=2025-12-31"), IF(_xlpm.usedCount=0, 2, MAX(2, _xlpm.usedCount/12*6*2)) ) -> 2 | I7: =IF(G7<H7,"X","O") -> O | J7: 204 | K7: KNAPP | M7: 114.52 | N7: =M7*$N$1 -> 196058.24 | P7: 2 | Q7: =COUNTIF('ASRS parts replacement'!F:F,D7) -> 0
C8: GEAR MOTOR ELR 350kw/7.5kw/3150 24V BL70M... | D8: 10410230_01 | E8: OSR Shuttle | F8: 90 | G8: 7 | H8: =_xlfn.LET( _xlpm.orderNum,#REF!, _xlpm.usedCount, COUNTIFS( 'ASRS parts replacement'!F:F, _xlpm.orderNum, 'ASRS parts replacement'!A:A, ">=2025-01-01", 'ASRS parts replacement'!A:A, "<=2025-12-31"), IF(_xlpm.usedCount=0, 2, MAX(2, _xlpm.usedCount/12*6*2)) ) -> 2 | I8: =IF(G8<H8,"X","O") -> O | J8: 205 | K8: KNAPP | M8: 668.55 | N8: =M8*$N$1 -> 1144557.6 | P8: 3 | Q8: =COUNTIF('ASRS parts replacement'!F:F,D8) -> 1
C9: GEAR MOTOR ELRkw/11.8 48V BL57AL-48V + ... | D9: 10395200_01 | E9: OSR Shuttle | F9: 180 | G9: 9 | H9: =_xlfn.LET( _xlpm.orderNum,#REF!, _xlpm.usedCount, COUNTIFS( 'ASRS parts replacement'!F:F, _xlpm.orderNum, 'ASRS parts replacement'!A:A, ">=2025-01-01", 'ASRS parts replacement'!A:A, "<=2025-12-31"), IF(_xlpm.usedCount=0, 2, MAX(2, _xlpm.usedCount/12*6*2)) ) -> 2 | I9: =IF(G9<H9,"X","O") -> O | J9: 205 | K9: KNAPP | M9: 458.11 | N9: =M9*$N$1 -> 784284.32 | P9: 3 | Q9: =COUNTIF('ASRS parts replacement'!F:F,D9) -> 0
C10: GEAR MOTOR ELRkw/33kw/3000 48V BL42YS-48V... | D10: 10540023_01 | E10: OSR Shuttle | F10: 90 | G10: 8 | H10: =_xlfn.LET( _xlpm.orderNum,#REF!, _xlpm.usedCount, COUNTIFS( 'ASRS parts replacement'!F:F, _xlpm.orderNum, 'ASRS parts replacement'!A:A, ">=2025-01-01", 'ASRS parts replacement'!A:A, "<=2025-12-31"), IF(_xlpm.usedCount=0, 2, MAX(2, _xlpm.usedCount/12*6*2)) ) -> 2 | I10: =IF(G10<H10,"X","O") -> O | J10: 242 | K10: KNAPP | M10: 555.82 | N10: =M10*$N$1 -> 951563.84 | P10: 3 | Q10: =COUNTIF('ASRS parts replacement'!F:F,D10) -> 2
C11: SHAFT COUPLING ROTEX GS12 COMPACT | D11: 10537096_01 | E11: OSR Shuttle | F11: 90 | G11: 28 | H11: =_xlfn.LET( _xlpm.orderNum,#REF!, _xlpm.usedCount, COUNTIFS( 'ASRS parts replacement'!F:F, _xlpm.orderNum, 'ASRS parts replacement'!A:A, ">=2025-01-01", 'ASRS parts replacement'!A:A, "<=2025-12-31"), IF(_xlpm.usedCount=0, 2, MAX(2, _xlpm.usedCount/12*6*2)) ) -> 2 | I11: =IF(G11<H11,"X","O") -> O | J11: 242 | K11: KNAPP | M11: 25.99 | N11: =M11*$N$1 -> 44494.88 | P11: 30 | Q11: =COUNTIF('ASRS parts replacement'!F:F,D11) -> 1
C12: ASSEMB. PRINTED CIRCUIT BOARD, SHUTTL... Replacement for 10676955_02 | D12: 10676955_08 | E12: OSR Shuttle | F12: 90 | G12: 6 | H12: =_xlfn.LET( _xlpm.orderNum,#REF!, _xlpm.usedCount, COUNTIFS( 'ASRS parts replacement'!F:F, _xlpm.orderNum, 'ASRS parts replacement'!A:A, ">=2025-01-01", 'ASRS parts replacement'!A:A, "<=2025-12-31"), IF(_xlpm.usedCount=0, 2, MAX(2, _xlpm.usedCount/12*6*2)) ) -> 2 | I12: =IF(G12<H12,"X","O") -> O | J12: 123 | K12: KNAPP | M12: 1059.9 | N12: =M12*$N$1 -> 1814548.8 | P12: 5 | Q12: =COUNTIF('ASRS parts replacement'!F:F,D12) -> 4
C13: TABLET, KAG ZEBRA ET51 10" RW INKL. R.. | D13: 10652991_01 | E13: ASRS | F13: 3 | G13: 1 | H13: 1 | I13: =IF(G13<H13,"X","O") -> O | J13: 213 | K13: KNAPP | L13: Zebra | M13: 3155.27 | N13: =M13*$N$1 -> 5401822.2 | P13: 2 | Q13: =COUNTIF('ASRS parts replacement'!F:F,D13) -> 2
B14: 납품확인서_NIKE(KR00022)_KNAPP Spare parts 5종 | C14: GEAR MOTOR ELR 220kw/10kw/3500 48V BL70S-... | D14: 10411034_01 | E14: OSR Shuttle | F14: 90 | G14: 9 | H14: =_xlfn.LET( _xlpm.orderNum,#REF!, _xlpm.usedCount, COUNTIFS( 'ASRS parts replacement'!F:F, _xlpm.orderNum, 'ASRS parts replacement'!A:A, ">=2025-01-01", 'ASRS parts replacement'!A:A, "<=2025-12-31"), IF(_xlpm.usedCount=0, 2, MAX(2, _xlpm.usedCount/12*6*2)) ) -> 2 | I14: =IF(G14<H14,"X","O") -> O | J14: 203 | K14: KNAPP | M14: 572.63 | N14: =M14*$N$1 -> 980342.56 | O14: 2023.11.24 | P14: 6 | Q14: =COUNTIF('ASRS parts replacement'!F:F,D14) -> 15
C15: LIFT DRIVE UNIT E60H4+EMT245 ELR 48VDC | D15: 10411039_01 | E15: OSR Shuttle | F15: 90 | G15: 7 | H15: =_xlfn.LET( _xlpm.orderNum,#REF!, _xlpm.usedCount, COUNTIFS( 'ASRS parts replacement'!F:F, _xlpm.orderNum, 'ASRS parts replacement'!A:A, ">=2025-01-01", 'ASRS parts replacement'!A:A, "<=2025-12-31"), IF(_xlpm.usedCount=0, 2, MAX(2, _xlpm.usedCount/12*6*2)) ) -> 2 | I15: =IF(G15<H15,"X","O") -> O | J15: 205 | K15: KNAPP | M15: 691.97 | N15: =M15*$N$1 -> 1184652.6 | P15: 6 | Q15: =COUNTIF('ASRS parts replacement'!F:F,D15) -> 9
C16: CURRENT COLLECTOR, 0815 2P1PH 35A REV... | D16: 10764610_01 | E16: OSR Shuttle | F16: 180 | G16: 104 | H16: =_xlfn.LET( _xlpm.orderNum,#REF!, _xlpm.usedCount, COUNTIFS( 'ASRS parts replacement'!F:F, _xlpm.orderNum, 'ASRS parts replacement'!A:A, ">=2025-01-01", 'ASRS parts replacement'!A:A, "<=2025-12-31"), IF(_xlpm.usedCount=0, 2, MAX(2, _xlpm.usedCount/12*6*2)) ) -> 2 | I16: =IF(G16<H16,"X","O") -> O | J16: 202 | K16: KNAPP | M16: 170.83 | N16: =M16*$N$1 -> 292460.96 | P16: 30 | Q16: =COUNTIF('ASRS parts replacement'!F:F,D16) -> 304
C17: BOGIE WHEEL, LFW ABLF EBG OSR_EVO | D17: 10567315_01 | E17: OSR Shuttle | F17: 360 | G17: 61 | H17: =_xlfn.LET( _xlpm.orderNum,#REF!, _xlpm.usedCount, COUNTIFS( 'ASRS parts replacement'!F:F, _xlpm.orderNum, 'ASRS parts replacement'!A:A, ">=2025-01-01", 'ASRS parts replacement'!A:A, "<=2025-12-31"), IF(_xlpm.usedCount=0, 2, MAX(2, _xlpm.usedCount/12*6*2)) ) -> 2 | I17: =IF(G17<H17,"X","O") -> O | J17: 242 | K17: KNAPP | M17: 64.6 | N17: =M17*$N$1 -> 110595.2 | P17: 20 | Q17: =COUNTIF('ASRS parts replacement'!F:F,D17) -> 20
C18: BOGIE WHEEL, QFW ABLF EBG, OSR_EVO | D18: 10567316_01 | E18: OSR Shuttle | F18: 360 | G18: 146 | H18: =_xlfn.LET( _xlpm.orderNum,#REF!, _xlpm.usedCount, COUNTIFS( 'ASRS parts replacement'!F:F, _xlpm.orderNum, 'ASRS parts replacement'!A:A, ">=2025-01-01", 'ASRS parts replacement'!A:A, "<=2025-12-31"), IF(_xlpm.usedCount=0, 2, MAX(2, _xlpm.usedCount/12*6*2)) ) -> 2 | I18: =IF(G18<H18,"X","O") -> O | J18: 242 | K18: KNAPP | M18: 53.39 | N18: =M18*$N$1 -> 91403.68 | P18: 20 | Q18: =COUNTIF('ASRS parts replacement'!F:F,D18) -> 45
B19: 납품확인서_KNAPP Spare parts 2종 구입 件 | C19: INCREMENTAL ENCODER, DBS36E-BBAP00S43 | D19: 10408341 | E19: OSR Shuttle | F19: 180 | G19: 8 | H19: =_xlfn.LET( _xlpm.orderNum,#REF!, _xlpm.usedCount, COUNTIFS( 'ASRS parts replacement'!F:F, _xlpm.orderNum, 'ASRS parts replacement'!A:A, ">=2025-01-01", 'ASRS parts replacement'!A:A, "<=2025-12-31"), IF(_xlpm.usedCount=0, 2, MAX(2, _xlpm.usedCount/12*6*2)) ) -> 2 | I19: =IF(G19<H19,"X","O") -> O | J19: 242 | K19: KNAPP | M19: 104.2 | N19: =M19*$N$1 -> 178390.4 | O19: 2024.03.27 | P19: 4 | Q19: =COUNTIF('ASRS parts replacement'!F:F,D19) -> 5
C20: STEPPER MOTOR HSY223-F06C + PX28S-16,... | D20: 10395201_01 | E20: OSR Shuttle | F20: 720 | G20: 19 | H20: =_xlfn.LET( _xlpm.orderNum,#REF!, _xlpm.usedCount, COUNTIFS( 'ASRS parts replacement'!F:F, _xlpm.orderNum, 'ASRS parts replacement'!A:A, ">=2025-01-01", 'ASRS parts replacement'!A:A, "<=2025-12-31"), IF(_xlpm.usedCount=0, 2, MAX(2, _xlpm.usedCount/12*6*2)) ) -> 2 | I20: =IF(G20<H20,"X","O") -> O | J20: 242 | K20: KNAPP | M20: 97.2 | N20: =M20*$N$1 -> 166406.4 | P20: 4 | Q20: =COUNTIF('ASRS parts replacement'!F:F,D20) -> 5
B21: 납품확인서_KNAPP Spare parts 1종 구입 件 | C21: RFID READER, IQT1-FP-R4-V1 | D21: 10404892 | E21: OSR Shuttle | F21: 90 | G21: 4 | H21: =_xlfn.LET( _xlpm.orderNum,#REF!, _xlpm.usedCount, COUNTIFS( 'ASRS parts replacement'!F:F, _xlpm.orderNum, 'ASRS parts replacement'!A:A, ">=2025-01-01", 'ASRS parts replacement'!A:A, "<=2025-12-31"), IF(_xlpm.usedCount=0, 2, MAX(2, _xlpm.usedCount/12*6*2)) ) -> 2 | I21: =IF(G21<H21,"X","O") -> O | J21: 114 | L21: Pepperl+Fuchs | M21: 258.19 | N21: =M21*$N$1 -> 442021.28 | O21: 2024.04.25 | P21: 2 | Q21: =COUNTIF('ASRS parts replacement'!F:F,D21) -> 12
